<?xml version="1.0" encoding="UTF-8"?>
<!-- Generated by org.testng.reporters.JUnitReportReporter -->
<testsuite hostname="5TS206424426L7" name="com.nbcuni.test.nbcidx.member.login.hmac.TC06_MemberLogout" tests="1" failures="0" timestamp="23 Sep 2014 20:07:47 GMT" time="2.602" errors="1">
  <testcase name="memberLogout_uuid" time="2.602" classname="com.nbcuni.test.nbcidx.member.login.hmac.TC06_MemberLogout">
    <error type="java.lang.AssertionError" message="More than 1 object is present in &#039;metadata/_logged_in/&#039; after member.logout and count of number of object is = 2">
      <![CDATA[java.lang.AssertionError: More than 1 object is present in 'metadata/_logged_in/' after member.logout and count of number of object is = 2
	at org.testng.AssertJUnit.fail(AssertJUnit.java:59)
	at com.nbcuni.test.nbcidx.MemberAPIs.memberLOGOUTResponse(MemberAPIs.java:310)
	at com.nbcuni.test.nbcidx.member.login.hmac.TC06_MemberLogout.memberLogout_uuid(TC06_MemberLogout.java:96)
	at sun.reflect.NativeMethodAccessorImpl.invoke0(Native Method)
	at sun.reflect.NativeMethodAccessorImpl.invoke(Unknown Source)
	at sun.reflect.DelegatingMethodAccessorImpl.invoke(Unknown Source)
	at java.lang.reflect.Method.invoke(Unknown Source)
	at org.testng.internal.MethodInvocationHelper.invokeMethod(MethodInvocationHelper.java:84)
	at org.testng.internal.Invoker.invokeMethod(Invoker.java:714)
	at org.testng.internal.Invoker.invokeTestMethod(Invoker.java:901)
	at org.testng.internal.Invoker.invokeTestMethods(Invoker.java:1231)
	at org.testng.internal.TestMethodWorker.invokeTestMethods(TestMethodWorker.java:127)
	at org.testng.internal.TestMethodWorker.run(TestMethodWorker.java:111)
	at java.util.concurrent.ThreadPoolExecutor.runWorker(Unknown Source)
	at java.util.concurrent.ThreadPoolExecutor$Worker.run(Unknown Source)
	at java.lang.Thread.run(Unknown Source)
]]>
    </error>
  </testcase> <!-- memberLogout_uuid -->
</testsuite> <!-- com.nbcuni.test.nbcidx.member.login.hmac.TC06_MemberLogout -->
